<?xml version="1.0"?>
<robot xmlns:xacro="http://ros.org/wiki/xacro" name="COMAN">

<!-- 
  ROS urdf definition of the COMAN humanoid robot by Istituto Italiano di Tecnologia
  
  DO NOT INCLUDE THIS FILE DIRECTLY! USE coman_robot.urdf.xacro INSTEAD!

  Author: Enrico Mingo & Alessio Rocchi

  Inertial matrix has to be in CoM frame (URDF specs)

  Velocity and effort limits are fake!
-->


<!-- ************ MODEL CONFIGURATION ************ -->
<xacro:include filename="$(find coman_urdf)/urdf/coman_config.urdf.xacro" />

<!-- ******************** FAKE LINKS ******************** -->

<!-- This links are defined in order to be compliant with http://www.ros.org/reps/rep-0120.html#coordinate-frames
and to define the end effectors of the robot -->

<!-- The coordinate frame called base_link is rigidly attached to the robot root body. It is recommended to choose the robot waist as its root body. The base_link can be attached to the root in any arbitrary position or orientation; for every hardware platform there will be a different place on the base that provides an obvious point of reference. Note that REP 103 [1] specifies a preferred orientation for frames. -->
  <link name="base_link"/>

<!-- position and orientation of the arm regardless of the tool (grasping device for instance) attached to it -->
  <link name="l_wrist"/>
  <link name="r_wrist"/>


<!--  position and orientation of the leg regardless of the support body geometry -->
  <link name="l_ankle"/>
  <link name="r_ankle"/>

<!-- position and orientation of the left leg support body. The (X,Y) plane of this frame must be coplanar with the support body contact surface. It is recommended to choose the origin as the projection of the support body origin on the contact surface. The Z coordinate of this frame should be on the ground level when standing. -->
  <link name="l_sole"/>
  <link name="r_sole"/>

<!--  position and orientation of the leg toe body. The (X,Y) plan of this frame must be coplanar with the toe body contact surface. It is recommended to choose the origin as the projection of the body center on the contact surface. -->
  <link name="l_toe"/>
  <link name="r_toe"/>

<!-- The coordinate frame called torso is attached to the lowest body of the model which is a parent of l_gripper, r_gripper and gaze. -->
 <link name="torso"/>

<!-- Head -->
<xacro:if value="${GAZEBO_COMAN_USES_XTION}">
	<link name ="Xtion_body">
    <inertial>
      <origin xyz="0.047 0.0 0.40" rpy="0 0 0"/>
      <mass value="0.39"/>
      <inertia ixx="0.01"  ixy="3.34E-7"  ixz="-2.66E-4" iyy="0.009" iyz="1.97E-6" izz="5.1E-4" />
    </inertial>
    <visual>
      <origin xyz="-0.020281504 0.0 -0.68662053" rpy="0 0 -3.14159265359"/>
      <geometry name="Xtion_body_visual">
        <mesh filename="package://coman_urdf/meshes/collada/Xtion/xtion_base.dae" scale="0.03937 0.03937 0.03937" />
      </geometry>
    </visual>
    <collision>
      <origin xyz="-0.020281504 0.0 -0.68662053" rpy="0 0 -3.14159265359"/>
      <geometry name="Xtion_body_collision">
        <mesh filename="package://coman_urdf/meshes/collada/simple/Xtion/xtion_base.stl" scale="0.03937 0.03937 0.03937" />
      </geometry>             
    </collision>
  </link>

  <link name ="Xtion_cam_body">
    <inertial>
      <origin xyz="0.0 0.0 0.0225" rpy="0 0 0"/>
      <mass value="0.2"/>
      <inertia ixx="0.00053"  ixy="0.0"  ixz="0.0" iyy="0.00008" iyz="0.0" izz="0.00053" />
    </inertial>
    <visual>
      <origin xyz="-0.0915 0.0 -1.2778" rpy="0 0 -3.14159265359"/>
      <geometry name="Xtion_cam_body_visual">
        <mesh filename="package://coman_urdf/meshes/collada/Xtion/xtion_cam_body.dae" scale="0.001 0.001 0.001" />
      </geometry>
    </visual>
    <collision>
      <origin xyz="-0.0915 0.0 -1.2778" rpy="0 0 -3.14159265359"/>
      <geometry name="Xtion_cam_body_collision">
        <mesh filename="package://coman_urdf/meshes/collada/simple/Xtion/xtion_cam_body.stl" scale="0.001 0.001 0.001" />
      </geometry>             
    </collision>
  </link>

</xacro:if>

<link name="gaze"/>  

<!-- ************ COMAN BASE ************** -->
<xacro:include filename="$(find coman_urdf)//urdf/coman_base.urdf.xacro"/>

<!-- ************ FOREARMS ************ -->
<xacro:if value="${GAZEBO_COMAN_USES_NO_FOREARMS}">
      <xacro:include filename="$(find coman_urdf)/urdf/forearms/no_forearms/no_forearms.urdf.xacro" />
  </xacro:if>

  <xacro:if value="${GAZEBO_COMAN_USES_7DOF_FOREARMS_DRC_14}">
      <xacro:include filename="$(find coman_urdf)/urdf/forearms/7DOF_forearms_DRC_14/7DOF_forearms_DRC_14.urdf.xacro" />
  </xacro:if>

<!-- ************ HANDS ************ -->

  <xacro:if value="${GAZEBO_COMAN_USES_7DOF_FOREARMS_DRC_14}">

   <joint name="l_wrist_joint" type="fixed">
     <parent link="LWrMot3"/>
     <child link="l_wrist"/>
     <origin xyz="0 0 0" rpy="0 0 0" />
   </joint>

    <joint name="r_wrist_joint" type="fixed">
      <parent link="RWrMot3"/>
      <child link="r_wrist"/>
      <origin xyz="0 0 0" rpy="0 0 0" />
    </joint>

    <xacro:include filename="$(find coman_urdf)/urdf/soft_hand.urdf.xacro" />	

    <xacro:if value="${GAZEBO_COMAN_USES_SOFTHANDS_DRC_sw1_14}">
      <joint name="r_handj" type="fixed">
        <parent link="RWrMot3"/>
        <child link="RSoftHand"/>
        <origin xyz="0 0 -0.07" rpy="0 0 0"/>
      </joint>

      <joint name="l_handj" type="fixed">
        <parent link="LWrMot3"/>
        <child link="LSoftHand"/>
        <origin xyz="0 0 -0.07" rpy="0 0 0"/>
      </joint>
    </xacro:if>

    <xacro:unless value="${GAZEBO_COMAN_USES_SOFTHANDS_DRC_sw1_14}">
      <joint name="r_handj" type="fixed">
        <parent link="RWrMot3"/>
        <child link="RSoftHand"/>
        <origin xyz="0 0 -0.04" rpy="-3.1415 0 0"/>
        <axis xyz="1 0 0" />
        <limit velocity="4.0" effort="5" lower="0.0" upper="1.57075" />
        <dynamics friction="0" damping="3.0"/>
      </joint>

      <joint name="l_handj" type="revolute">
        <parent link="LWrMot3"/>
        <child link="LSoftHand"/>
        <origin xyz="0 0 -0.04" rpy="0 0 0"/>
        <axis xyz="1 0 0" />
        <limit velocity="4.0" effort="5" lower="-1.57075" upper="0.0" />
        <dynamics friction="0" damping="3.0"/>
      </joint>
    </xacro:unless>

  </xacro:if>

<xacro:if value="${GAZEBO_COMAN_USES_NO_FOREARMS}">
	<joint name="l_wrist_joint" type="fixed">
	  <parent link="LElb"/>
	  <child link="l_wrist"/>
	  <origin xyz="-0.015 0 -0.22" rpy="0 0 0" />
	</joint>

        <joint name="r_wrist_joint" type="fixed">
	  <parent link="RElb"/>
	  <child link="r_wrist"/>
	  <origin xyz="-0.015 0 -0.22" rpy="0 0 0" />
	</joint>
</xacro:if>

</robot>




