<?xml version="1.0"?>
<robot xmlns:xacro="http://ros.org/wiki/xacro">

<xacro:property name="PI" value="3.14159265359" />
<xacro:property name="SF" value="0.03937" /> <!-- Scale factor for meshes -->


<!-- LINKS -->

<!-- RIGHT ARM -->
<link name ="RShp">
    <inertial>
      <origin xyz="0.0099500565 -0.038682024 1.6446924E-4" rpy="0 0 0"/>
      <mass value="0.56782202"/>
      <inertia ixx="7.8337456E-4"  ixy="1.9035768E-4"  ixz="-3.0037676E-6" iyy="6.3399921E-4" iyz="4.3840774E-6" izz="0.001008054" />
    </inertial>
    <visual>
      <origin xyz="-0.005305 0.0825 -0.844329" rpy="0 0 ${PI}"/>
      <material name="dark_grey"/>
      <geometry name="RShp_visual">
        <mesh filename="package://coman_urdf/meshes/collada/rarm0.stl" scale="${SF} ${SF} ${SF}" />
      </geometry>
    </visual>
    <collision>
      <origin xyz="-0.005305 0.0825 -0.844329" rpy="0 0 ${PI}"/>
      <geometry name="RShp_collision">
        <mesh filename="package://coman_urdf/meshes/collada/simple/simple_asm0001_collada_24_prt.stl" scale="${SF} ${SF} ${SF}" />
      </geometry>             
    </collision>
</link>

<link name ="RShr">
    <inertial>
      <origin xyz="-0.0038936743 2.2022151E-6 -0.0048616005" rpy="0 0 0"/>
      <mass value="0.77683752"/>
      <inertia ixx="4.5812904E-4"  ixy="-2.4111086E-7"  ixz="9.2521185E-6" iyy="4.3089204E-4" iyz="-4.7216950E-7" izz="3.4174855E-4" />
    </inertial>
    <visual>
      <origin xyz="-0.005305 0.1558 -0.844329" rpy="0 0 ${PI}"/>
      <material name="dark_grey"/>
      <geometry name="RShr_visual">
        <mesh filename="package://coman_urdf/meshes/collada/rarm1.stl" scale="${SF} ${SF} ${SF}" />
      </geometry>
    </visual>
    <collision>
      <origin xyz="-0.005305 0.1558 -0.844329" rpy="0 0 ${PI}"/>
      <geometry name="RShr_collision">
        <mesh filename="package://coman_urdf/meshes/collada/simple/simple_asm0001_collada_23_prt.stl" scale="${SF} ${SF} ${SF}" />
      </geometry>             
    </collision>
</link>

<link name ="RShy">
    <inertial>
      <origin xyz="0.0022714213 -0.0071091517 -0.057455221" rpy="0 0 0"/>
      <mass value="1.0462304"/>
      <inertia ixx="0.0030934574"  ixy="6.6702837E-5"  ixz="3.0222291E-4" iyy="0.0029181573" iyz="-5.2663661E-4" izz="8.0830389E-4" />
    </inertial>
    <visual>
      <origin xyz="-0.005305 0.1558 -0.79952053" rpy="0 0 ${PI}"/>
      <material name="dark_grey"/>
      <geometry name="RShy_visual">
        <mesh filename="package://coman_urdf/meshes/collada/rarm2.stl" scale="${SF} ${SF} ${SF}" />
      </geometry>
    </visual>
    <collision>
      <origin xyz="-0.005305 0.1558 -0.79952053" rpy="0 0 ${PI}"/>
      <geometry name="RShy_collision">
        <mesh filename="package://coman_urdf/meshes/collada/simple/simple_asm0001_collada_22_prt.stl" scale="${SF} ${SF} ${SF}" />
      </geometry>             
    </collision>
</link>

<link name ="RElb">
        <inertial>
          <origin xyz="-6.5553403E-4 -9.3464748E-4 -9.3101289E-4" rpy="0 0 0"/>
          <mass value="0.63306933"/>
          <inertia ixx="2.2599075E-4"  ixy="-2.6376470E-7"  ixz="-9.8007285E-6" iyy="2.7781302E-4" iyz="-2.0435288E-6" izz="2.1878992E-4" />
        </inertial>
        <visual>
          <origin xyz="0 0 0" rpy="-1.570796326795 1.570796326795 0"/>
          <material name="dark_grey"/>
          <geometry name="RElb_visual">
            <mesh filename="package://coman_urdf/meshes/collada/forearms/elbow.stl" scale="1.0 1.0 1.0" />
          </geometry>
        </visual>
        <collision>
          <origin xyz="0 0 0" rpy="-1.570796326795 1.570796326795 0"/>
          <geometry name="RElb_collision">
            <mesh filename="package://coman_urdf/meshes/collada/simple/forearms/elbow.stl" scale="1.0 1.0 1.0" />
          </geometry>             
        </collision>
</link>

<!-- LEFT ARM -->
<link name ="LShp">
    <inertial>
      <origin xyz="0.0099500565 0.038682024 1.6446924E-4" rpy="0 0 0"/>
      <mass value="0.56782202"/>
      <inertia ixx="7.8337456E-4"  ixy="-1.9035768E-4"  ixz="-3.0037676E-6" iyy="6.3399921E-4" iyz="-4.3840774E-6" izz="0.001008054" />
    </inertial>
    <visual>
      <origin xyz="-0.005305 -0.0825 -0.844329" rpy="0 0 ${PI}"/>
      <material name="dark_grey"/>
      <geometry name="LShp_visual">
        <mesh filename="package://coman_urdf/meshes/collada/larm0.stl" scale="${SF} ${SF} ${SF}" />
      </geometry>
    </visual>
    <collision>
      <origin xyz="-0.005305 -0.0825 -0.844329" rpy="0 0 ${PI}"/>
      <geometry name="LShp_collision">
        <mesh filename="package://coman_urdf/meshes/collada/simple/simple_asm0001_collada_14_prt.stl" scale="${SF} ${SF} ${SF}" />
      </geometry>             
    </collision>
</link>

<link name ="LShr">
    <inertial>
      <origin xyz="-0.0038936743 -2.2022151E-6 -0.0048616005" rpy="0 0 0"/>
      <mass value="0.77683752"/>
      <inertia ixx="4.5812904E-4"  ixy="2.4111086E-7"  ixz="9.2521185E-6" iyy="4.3089204E-4" iyz="4.721695E-7" izz="3.4174855E-4" />
    </inertial>
    <visual>
      <origin xyz="-0.005305 -0.1558 -0.844329" rpy="0 0 ${PI}"/>
      <material name="dark_grey"/>
      <geometry name="LShr_visual">
        <mesh filename="package://coman_urdf/meshes/collada/larm1.stl" scale="${SF} ${SF} ${SF}" />
      </geometry>
    </visual>
    <collision>
      <origin xyz="-0.005305 -0.1558 -0.844329" rpy="0 0 ${PI}"/>
      <geometry name="LShr_collision">
        <mesh filename="package://coman_urdf/meshes/collada/simple/simple_asm0001_collada_13_prt.stl" scale="${SF} ${SF} ${SF}" />
      </geometry>             
    </collision>
</link>

  <link name ="LShy">
    <inertial>
      <origin xyz="0.0022714213 0.0071091517 -0.057455221" rpy="0 0 0"/>
      <mass value="1.0462304"/>
      <inertia ixx="0.0030934574"  ixy="-6.6702837E-5"  ixz="3.0222291E-4" iyy="0.0029181573" iyz="5.2663661E-4" izz="8.0830389E-4" />
    </inertial>
    <visual>
      <origin xyz="-0.005305 -0.1558 -0.79952053" rpy="0 0 ${PI}"/>
      <material name="dark_grey"/>
      <geometry name="LShy_visual">
        <mesh filename="package://coman_urdf/meshes/collada/larm2.stl" scale="${SF} ${SF} ${SF}" />
      </geometry>
    </visual>
    <collision>
      <origin xyz="-0.005305 -0.1558 -0.79952053" rpy="0 0 ${PI}"/>
      <geometry name="LShy_collision">
        <mesh filename="package://coman_urdf/meshes/collada/simple/simple_asm0001_collada_12_prt.stl" scale="${SF} ${SF} ${SF}" />
      </geometry>             
    </collision>
  </link>

    <link name ="LElb">
        <inertial>
          <origin xyz="-6.5553403E-4 9.3464748E-4 -9.3101289E-4" rpy="0 0 0"/>
          <mass value="0.63306933"/>
          <inertia ixx="2.2599075E-4"  ixy="2.6376470E-7"  ixz="-9.8007285E-6" iyy="2.7781302E-4" iyz="2.0435288E-6" izz="2.1878992E-4" />
        </inertial>
        <visual>
          <origin xyz="0 0 0" rpy="-1.570796326795 1.570796326795 0"/>
          <material name="dark_grey"/>
          <geometry name="LElb_visual">
            <mesh filename="package://coman_urdf/meshes/collada/forearms/elbow.stl" scale="1.0 1.0 1.0" />
          </geometry>
        </visual>
        <collision>
          <origin xyz="0 0 0" rpy="-1.570796326795 1.570796326795 0"/>
          <geometry name="LElb_collision">
            <mesh filename="package://coman_urdf/meshes/collada/simple/forearms/elbow.stl" scale="1.0 1.0 1.0" />
          </geometry>             
        </collision>
      </link>

<!-- JOINTS -->

<!-- RIGHT ARM -->
<joint name="RShSag" type="revolute">
    <parent link="DWYTorso"/>
    <child link="RShp"/>
    <origin xyz="-0.014976503999999998 -0.0825 0.15770847" rpy="0 0 0" />
    <axis xyz="0 1 0" />
    <limit effort="200" lower="-3.14" upper="3.14" velocity="4.0"/>
    <dynamics friction="0" damping="3.0"/>
</joint>

<joint name="RShLat" type="revolute">
    <parent link="RShp"/>
    <child link="RShr"/>
    <origin xyz="0.0 -0.07329999999999999 0.0" rpy="0 0 0" />
    <axis xyz="1 0 0" />
    <limit effort="200" lower="-3.14" upper="3.14" velocity="4.0"/>
    <dynamics friction="0" damping="3.0"/>
</joint>

<joint name="RShYaw" type="revolute">
    <parent link="RShr"/>
    <child link="RShy"/>
    <origin xyz="0.0 0.0 -0.04480846999999999" rpy="0 0 0" />
    <axis xyz="0 0 1" />
    <limit effort="200" lower="-3.14" upper="3.14" velocity="4.0"/>
    <dynamics friction="0" damping="3.0"/> 
</joint>

  <joint name="RElbj" type="revolute">
    <parent link="RShy"/>
    <child link="RElb"/>
    <origin xyz="0.015 0.0 -0.13519152999999998" rpy="0 0 0" />
    <axis xyz="0 1 0" />
    <limit effort="200" lower="-3.14" upper="3.14" velocity="4.0"/>
    <dynamics friction="0" damping="3.0"/>
  </joint>

<!-- LEFT ARM -->
<joint name="LShSag" type="revolute">
    <parent link="DWYTorso"/>
    <child link="LShp"/>
    <origin xyz="-0.014976503999999998 0.0825 0.15770847" rpy="0 0 0" />
    <axis xyz="0 1 0" />
    <limit effort="200" lower="-3.14" upper="3.14" velocity="4.0"/>
    <dynamics friction="0" damping="3.0"/>
</joint>

<joint name="LShLat" type="revolute">
    <parent link="LShp"/>
    <child link="LShr"/>
    <origin xyz="0.0 0.07329999999999999 0.0" rpy="0 0 0" />
    <axis xyz="1 0 0" />
    <limit effort="200" lower="-3.14" upper="3.14" velocity="4.0"/>
    <dynamics friction="0" damping="3.0"/>
</joint>

<joint name="LShYaw" type="revolute">
    <parent link="LShr"/>
    <child link="LShy"/>
    <origin xyz="0.0 0.0 -0.04480846999999999" rpy="0 0 0" />
    <axis xyz="0 0 1" />
    <limit effort="200" lower="-3.14" upper="3.14" velocity="4.0"/>
    <dynamics friction="0" damping="3.0"/>
</joint>

  <joint name="LElbj" type="revolute">
    <parent link="LShy"/>
    <child link="LElb"/>
    <origin xyz="0.015 0.0 -0.13519152999999998" rpy="0 0 0" />
    <axis xyz="0 1 0" />
    <limit effort="200" lower="-3.14" upper="3.14" velocity="4.0"/>
    <dynamics friction="0" damping="3.0"/>
  </joint>

</robot>
