<?xml version="1.0"?>
<robot xmlns:xacro="http://ros.org/wiki/xacro">

<xacro:property name="PI" value="3.14159265359" />
<xacro:property name="PI_2" value="1.57079632679" />
<xacro:property name="SF" value="0.03937" /> <!-- Scale factor for meshes -->
<xacro:property name="base_link_z_translation" value="-0.52" />
<xacro:property name="cos_20" value="0.93969262078" />
<xacro:property name="sin_20" value="0.34202014332" />


<!-- LINKS -->
<!-- This links are defined in order to be compliant with http://www.ros.org/reps/rep-0120.html#coordinate-frames
and to define the end effectors of the robot

The coordinate frame called base_link is rigidly attached to the robot root body. It is recommended to choose the robot waist as its root body. The base_link can be attached to the root in any arbitrary position or orientation; for every hardware platform there will be a different place on the base that provides an obvious point of reference. Note that REP 103 [1] specifies a preferred orientation for frames. -->
<link name="base_link"/>

<!-- The coordinate frame called torso is attached to the lowest body of the model which is a parent of l_gripper, r_gripper and gaze. -->
 <link name="torso"/>

<link name="Waist">
    <inertial>
      <origin xyz="-0.026391145 -5.8216364E-4 0.052632312" rpy="0.0 0.0 0.0"/>
      <mass value="1.8008695"/>
      <inertia ixx="0.0051032982"  ixy="-5.7170981E-5"  ixz="0.0016920543" iyy="0.006241636" iyz="1.7225949E-5" izz="0.0024517762" />
    </inertial>
    <visual>
      <origin xyz="0 0 ${base_link_z_translation}" rpy="0 0 ${PI}"/>
      <material name="dark_grey"/>
      <geometry name="Waist_visual">
        <!--mesh filename="package://coman_urdf/meshes/collada/asm0001_collada_07_prt.dae" scale="${SF} ${SF} ${SF}"/-->
        <mesh filename="package://coman_urdf/meshes/collada/torso0.stl" scale="${SF} ${SF} ${SF}"/>
      </geometry>
    </visual> 
    <collision>
      <origin xyz="0 0 ${base_link_z_translation}" rpy="0 0 ${PI}"/>
      <geometry name="Waist_collision">
        <mesh filename="package://coman_urdf/meshes/collada/simple/simple_asm0001_collada_07_prt.stl" scale="${SF} ${SF} ${SF}"/>
      </geometry>             
    </collision>   
</link>

  <link name ="DWL">
    <inertial>
      <origin xyz="4.2999707E-4 -0.0097650317 0.033011157" rpy="0 0 0"/>
      <mass value="0.54588774"/>
      <inertia ixx="9.7126578E-4"  ixy="-7.2101244E-7"  ixz="1.1440119E-6" iyy="7.4686706E-4" iyz="-1.7450917E-4" izz="6.2196235E-4" />
    </inertial>
    <visual>
      <origin xyz="-0.020281504 0 -0.63912053" rpy="0 0 ${PI}"/>
      <geometry name="DWL_visual">
        <mesh filename="package://coman_urdf/meshes/collada/asm0001_collada_09_prt.dae" scale="${SF} ${SF} ${SF}" />
      </geometry>
    </visual>
    <collision>
      <origin xyz="-0.020281504 0 -0.63912053" rpy="0 0 ${PI}"/>
      <geometry name="DWL_collision">
        <mesh filename="package://coman_urdf/meshes/collada/simple/simple_asm0001_collada_09_prt.stl" scale="${SF} ${SF} ${SF}" />
      </geometry>             
    </collision>
  </link>

  <link name ="DWS">
    <inertial>
      <origin xyz="-0.0021273416 0.0033575235 -0.0010076896" rpy="0 0 0"/>
      <mass value="0.75398402"/>
      <inertia ixx="3.4093348E-4"  ixy="-6.2120042E-6"  ixz="-1.3863473E-6" iyy="3.9581916E-4" iyz="1.443019E-6" izz="3.7449753E-4" />
    </inertial>
    <visual>
      <origin xyz="-0.020281504 0 -0.63912053" rpy="0 0 ${PI}"/>
      <geometry name="DWS_visual">
        <mesh filename="package://coman_urdf/meshes/collada/asm0001_collada_08_prt.dae" scale="${SF} ${SF} ${SF}" />
      </geometry>
    </visual>
    <collision>
      <origin xyz="-0.020281504 0 -0.63912053" rpy="0 0 ${PI}"/>
      <geometry name="DWS_collision">
        <mesh filename="package://coman_urdf/meshes/collada/simple/simple_asm0001_collada_08_prt.stl" scale="${SF} ${SF} ${SF}" />
      </geometry>             
    </collision>
  </link>

  <link name ="DWYTorso">
    <inertial>
      <origin xyz="-0.0358501 1.8286043E-5 0.117557148" rpy="0 0 0"/>
      <mass value="6.3617175"/>
      <inertia ixx="0.034089342"  ixy="-9.8308572E-6"  ixz="-7.5649290E-4" iyy="0.030117357" iyz="6.2443771E-6" izz="0.025296582" />
    </inertial>
    <visual>
      <origin xyz="-0.020281504 0.0 -0.68662053" rpy="0 0 ${PI}"/>
      <geometry name="DWYTorso_visual">
        <mesh filename="package://coman_urdf/meshes/collada/asm0001_collada_10_prt.dae" scale="${SF} ${SF} ${SF}" />
      </geometry>
    </visual>
    <collision>
      <origin xyz="-0.020281504 0.0 -0.68662053" rpy="0 0 ${PI}"/>
      <geometry name="DWYTorso_collision">
        <mesh filename="package://coman_urdf/meshes/collada/simple/simple_asm0001_collada_10_prt.stl" scale="${SF} ${SF} ${SF}" />
      </geometry>             
    </collision>
  </link>

<!-- JOINTS -->
<joint name="base_joint" type="fixed">
    <parent link="base_link"/>
    <child link="Waist"/>
    <origin xyz="0 0 0" rpy="0 0 0" />
</joint>

<joint name="torso_joint" type="fixed">
    <parent link="DWYTorso"/>
    <child link="torso"/>
    <origin xyz="-0.014976503999999998 0 0.15770847" rpy="0 0 0" /> 
</joint>

<joint name="WaistLat" type="revolute"> 
    <parent link="Waist"/>
    <child link="DWL"/>
    <origin xyz="0.020281504 0 0.11912053" rpy="0 0 0" />
    <axis xyz="${cos_20} 0 ${sin_20}" />
    <limit velocity="4.0" effort="50" lower="-0.5236" upper="0.5235" />
    <!-- dynamics friction="0" damping="0.3"/ -->
    <dynamics friction="0" damping="3.0"/> 
</joint>

  <joint name="WaistSag" type="revolute"> 
    <parent link="DWL"/>
    <child link="DWS"/>
    <origin xyz="0 0 0" rpy="0 0 0" />
    <axis xyz="0 1 0" />
    <limit velocity="4.0" effort="50" lower="-0.3491" upper="0.8727" />
    <dynamics friction="0" damping="3.0"/>
  </joint>

  <joint name="WaistYaw" type="revolute">
    <parent link="DWS"/>
    <child link="DWYTorso"/>
    <origin xyz="0 0 0.04749999" rpy="0 0 0" />
    <axis xyz="0 0 1" />
    <limit velocity="4.0" effort="50" lower="-1.3963" upper="1.3962" />
    <dynamics friction="0" damping="3.0"/>
  </joint>

</robot>
