<?xml version="1.0"?>
<robot xmlns:xacro="http://ros.org/wiki/xacro">

  <joint name="LForearmPlate" type="revolute">
    <parent link="LElb"/>
    <child link="LForearm"/>
    <origin xyz="-0.015 0.0 -0.051" rpy="0 0 0"/>
    <axis xyz="0 0 1" />
    <limit velocity="4.0" effort="50" lower="-1.5708" upper="1.5708" />
    <dynamics friction="0" damping="0.03"/>
  </joint>

  <joint name="LWrj1" type="revolute">
    <parent link="LForearm"/>
    <child link="LWrMot2"/>
    <origin xyz="0 0 -0.14368" rpy="0 0 0"/>
    <axis xyz="0 1 0"/>
    <limit velocity="4.0" effort="50" lower="-0.524" upper="0.524" />
    <dynamics friction="0" damping="0.03"/>
  </joint>

  <joint name="LWrj2" type="revolute">
    <parent link="LWrMot2"/>
    <child link="LWrMot3"/>
    <origin xyz="0 0 0.0" rpy="0 0 0"/>
    <axis xyz="1 0 0"/>
    <limit velocity="4.0" effort="50" lower="-0.785375" upper="1.395" />
    <dynamics friction="0" damping="0.03"/>
  </joint>

</robot>